Workbook

Sheet Boilers
B2: Boilers
C3: Boilers, Thermopacks and their Fuels | R3: Sp. Steam Cost
B4: Month | C4: 1 TPH | F4: Electricity Consumed | G4: Chemical Consumption | I4: Cost of Briquettes (Rs./kg) | J4: Cost of Firewood (Rs. /kg) | K4: Electricty Cost | L4: Chemical cost | N4: Boiler Fuel Cost (Rs.) | O4: Boiler Operational Cost (Rs.) | P4: Total Water supplied to boiler | Q4: Steam generated | R4: Indirect | S4: Direct | T4: Total Cost
C5: Running Hours | D5: Fuel Consumption (Firewood) (kg) | E5: Fuel Consumption (Briquettes) (kg) | G5: Ancotreat 1240 R (kg) | H5: Ancotreat 1385 I (kg) | L5: Ancotreat 1240 R (kg) | M5: Ancotreat 1385 I (kg) | Q5: (MT) | R5: Rs./MT | S5: Rs./MT | T5: Rs./Kg
B6: 45658 | C6: 388 | D6: 61750 | E6: 2430 | G6: 24 | H6: 24 | I6: 8.6 | J6: 5 | K6: ='Electrcity Data'!M5 -> 10.388894 | L6: 68 | M6: 76.5 | N6: =I6*E6+J6*D6 -> 329648 | O6: =N6+L6*G6+M6*H6+K6*F6 -> 333116 | P6: 290 | Q6: 290 | R6: =F6*K6/Q6 -> 0 | S6: =(L6*G6+M6*H6+J6*D6)/Q6 -> 1076.6138 | T6: =O6/Q6 -> 1148.6759
B7: 45689 | C7: 388 | D7: 58600 | E7: 0 | G7: 24 | H7: 24 | I7: 8.6 | J7: 5 | K7: ='Electrcity Data'!M6 -> 9.1966195 | L7: 68 | M7: 76.5 | N7: =I7*E7+J7*D7 -> 293000 | O7: =N7+L7*G7+M7*H7+K7*F7 -> 296468 | P7: 267.8 | Q7: 267.8 | R7: =F7*K7/Q7 -> 0 | S7: =(L7*G7+M7*H7+J7*D7)/Q7 -> 1107.05 | T7: =O7/Q7 -> 1107.05
B8: 45717 | C8: 362 | D8: 51800 | E8: 0 | G8: 25 | H8: 25 | I8: 8.6 | J8: 5 | K8: ='Electrcity Data'!M7 -> 10.015294 | L8: 68 | M8: 76.5 | N8: =I8*E8+J8*D8 -> 259000 | O8: =N8+L8*G8+M8*H8+K8*F8 -> 262612.5 | P8: 217.56 | Q8: 217.56 | R8: =F8*K8/Q8 -> 0 | S8: =(L8*G8+M8*H8+J8*D8)/Q8 -> 1207.0808 | T8: =O8/Q8 -> 1207.0808
B9: 45748 | C9: 400 | D9: 77500 | E9: 0 | G9: 25 | H9: 25 | I9: 8.6 | J9: 5 | K9: ='Electrcity Data'!M8 -> 10.736692 | L9: 68 | M9: 76.5 | N9: =I9*E9+J9*D9 -> 387500 | O9: =N9+L9*G9+M9*H9+K9*F9 -> 391112.5 | P9: 325 | Q9: 325 | R9: =F9*K9/Q9 -> 0 | S9: =(L9*G9+M9*H9+J9*D9)/Q9 -> 1203.4231 | T9: =O9/Q9 -> 1203.4231
B10: 45778 | C10: 434 | D10: 65290 | E10: 0 | G10: 26 | H10: 26 | I10: 8.6 | J10: 5 | K10: ='Electrcity Data'!M9 -> 8.4844151 | L10: 68 | M10: 76.5 | N10: =I10*E10+J10*D10 -> 326450 | O10: =N10+L10*G10+M10*H10+K10*F10 -> 330207 | P10: 29.38 | Q10: 29.38 | R10: =F10*K10/Q10 -> 0 | S10: =(L10*G10+M10*H10+J10*D10)/Q10 -> 11239.176 | T10: =O10/Q10 -> 11239.176
B11: 45809 | C11: 419 | D11: 57900 | E11: 0 | G11: 25 | H11: 25 | I11: 8.6 | J11: 5 | K11: ='Electrcity Data'!M10 -> 55.891182 | L11: 68 | M11: 76.5 | N11: =I11*E11+J11*D11 -> 289500 | O11: =N11+L11*G11+M11*H11+K11*F11 -> 293112.5 | P11: 33 | Q11: 33 | R11: =F11*K11/Q11 -> 0 | S11: =(L11*G11+M11*H11+J11*D11)/Q11 -> 8882.197 | T11: =O11/Q11 -> 8882.197
B12: 45839
B13: 45870
B14: 45901
B15: 45931
B16: 45962 | N16: =I16*D16+J16*E16 -> 0 | O16: =N16+L16*G16+M16*H16+K16*F16 -> 0 | R16: =F16*K16/Q16 -> #DIV/0! | S16: =T16-R16 -> #DIV/0! | T16: =O16/Q16 -> #DIV/0!
B17: 45992 | N17: =I17*D17+J17*E17 -> 0 | O17: =N17+L17*G17+M17*H17+K17*F17 -> 0 | R17: =F17*K17/Q17 -> #DIV/0! | S17: =T17-R17 -> #DIV/0! | T17: =O17/Q17 -> #DIV/0!
B18: Total | C18: =+SUM(C6:C17) -> 2391 | D18: =+SUM(D6:D17) -> 372840 | E18: =+SUM(E6:E17) -> 2430 | F18: =+SUM(F6:F17) -> 0 | G18: =+SUM(G6:G17) -> 149 | H18: =+SUM(H6:H17) -> 149 | J18: =+SUM(J6:J17) -> 30 | K18: =+SUM(K6:K17) -> 104.7131 | L18: =+SUM(L6:L17) -> 408 | M18: =+SUM(M6:M17) -> 459 | N18: =+SUM(N6:N17) -> 1885098 | O18: =+SUM(O6:O17) -> 1906628.5 | Q18: =+SUM(Q6:Q17) -> 1162.74 | R18: =+SUM(R6:R17) -> #DIV/0! | S18: =+SUM(S6:S17) -> #DIV/0! | T18: =+SUM(T6:T17) -> #DIV/0!

Sheet DGs
B1: DGs and their Fuels
B2: DGs
B4: Month | C4: 125 KVA | F4: 500 KVA | I4: 320 KVA II | L4: Total Units generated | M4: Total Fuel Consumption (l) | N4: HSD Cost /l | O4: Total DG Operating cost (Rs.) | P4: Per Unit Electricity Cost
C5: Running Hours | D5: Fuel Consumption (l) | E5: Units Generated (KWh) | F5: Running Hours | G5: Fuel Consumption (l) | H5: Units Generated (KWh) | I5: Running Hours | J5: Fuel Consumption (l) | K5: Units Generated (KWh) | L5: Units Generated (KWh)
B6: 45658 | C6: 5.7 | D6: 60 | E6: 152 | F6: 0 | G6: 0 | H6: 0 | I6: 17.1 | J6: 760 | K6: 2980 | L6: =K6+H6 -> 2980 | M6: =G6+J6+D6 -> 820 | N6: 94.04 | O6: =N6*M6 -> 77112.8 | P6: =L6/M6 -> 3.6341463
B7: 45689 | F7: 0 | G7: 0 | H7: 0 | I7: 20.1 | J7: 795 | K7: 3220 | L7: =K7+H7 -> 3220 | M7: =G7+J7+D7 -> 795 | N7: 94.04 | O7: =N7*M7 -> 74761.8 | P7: =L7/M7 -> 4.0503145
B8: 45717 | F8: 6.4 | G8: 254 | H8: 896 | I8: 15.6 | J8: 547 | K8: 2095 | L8: =K8+H8 -> 2991 | M8: =G8+J8+D8 -> 801 | N8: 94.04 | O8: =N8*M8 -> 75326.04 | P8: =L8/M8 -> 3.7340824
B9: 45748 | F9: 0 | G9: 86 | H9: 0 | I9: 24.3 | J9: 525 | K9: 1638 | L9: =K9+H9 -> 1638 | M9: =G9+J9+D9 -> 611 | N9: 94.04 | O9: =N9*M9 -> 57458.44 | P9: =L9/M9 -> 2.6808511
B10: 45778 | F10: 0 | G10: 0 | H10: 0 | I10: 0 | J10: 550 | K10: 21.3 | L10: 550 | M10: =G10+J10+D10 -> 550 | N10: 94.04 | O10: =N10*M10 -> 51722 | P10: =L10/M10 -> 1
B11: 45809 | F11: 0 | G11: 165 | H11: 0 | I11: 0 | J11: 830 | K11: 20.7 | L11: 830 | M11: =G11+J11+D11 -> 995 | N11: 94.04 | O11: =N11*M11 -> 93569.8 | P11: =L11/M11 -> 0.83417085
B12: 45839
B13: 45870
B14: 45901
B15: 45931
B16: 45962 | M16: =J16+G16 -> 0 | O16: =N16*M16 -> 0 | P16: =L16/M16 -> #DIV/0!
B17: 45992 | L17: =K17+H17 -> 0 | M17: =J17+G17 -> 0 | O17: =N17*M17 -> 0 | P17: =L17/M17 -> #DIV/0!
B18: Total | H18: =+SUM(H6:H17) -> 896 | I18: =+SUM(I6:I17) -> 77.1 | J18: =+SUM(J6:J17) -> 4007 | L18: =+SUM(L6:L17) -> 12209 | M18: =+SUM(M6:M17) -> 4572 | N18: =+SUM(N6:N17) -> 564.24 | O18: =+SUM(O6:O17) -> 429950.88 | P18: =+SUM(P6:P17) -> #DIV/0!
B21: Calculation for running hours
B23: For 9 hours 15 minutes

Sheet Electrcity Data
B2: Electricty Details
B4: Month | C4: Unit | D4: State Electricity as per bill (non wheeled) | E4: Renewable Electricity | F4: DG Electricity Generated | G4: Total consumed | H4: Consumed in Production | I4: Consumed in Washing | J4: Office Use | K4: Monthly bill of State Electricity (Rs.) | L4: DG Fuel Cost for Electricity Generation (Rs.) | M4: Power Cost (Rs./Kwh) | N4: DG Electricity Share (%)
B5: 45658 | C5: KWh | D5: 54562 | E5: 10000 | F5: 3132 | G5: =F5+D6+E5 -> 66650 | H5: 56509 | I5: 1025 | J5: 160 | K5: 615307 | L5: =DGs!O6 -> 77112.8 | M5: =(L5+K5)/G5 -> 10.388894 | N5: =F5/G5 -> 0.046991748
B6: 45689 | C6: KWh | D6: 53518 | E6: 10000 | F6: 3220 | G6: =F6+D7+E6 -> 73954 | H6: 55734 | I6: 844 | J6: 160 | K6: 605365 | L6: =DGs!O7 -> 74761.8 | M6: =(L6+K6)/G6 -> 9.1966195 | N6: =F6/G6 -> 0.043540579
B7: 45717 | C7: KWh | D7: 60734 | E7: 10000 | F7: 2991 | G7: =F7+D8+E7 -> 73625 | H7: =G7-I7-J7 -> 73465 | I7: 0 | J7: 160 | K7: 662050 | L7: =DGs!O8 -> 75326.04 | M7: =(L7+K7)/G7 -> 10.015294 | N7: =F7/G7 -> 0.040624788
B8: 45748 | C8: KWh | D8: 60634 | E8: 10000 | F8: 1638 | G8: =F8+D9+E8 -> 67201 | H8: =G8-I8-J8 -> 65803 | I8: 1238 | J8: 160 | K8: 664058 | L8: =DGs!O9 -> 57458.44 | M8: =(L8+K8)/G8 -> 10.736692 | N8: =F8/G8 -> 0.024374637
B9: 45778 | C9: KWh | D9: 55563 | E9: 10000 | F9: 1964 | G9: =F9+D10+E9 -> 78730 | H9: =G9-I9-J9 -> 77201 | I9: 1369 | J9: 160 | K9: 616256 | L9: =DGs!O10 -> 51722 | M9: =(L9+K9)/G9 -> 8.4844151 | N9: =F9/G9 -> 0.024946018
B10: 45809 | C10: KWh | D10: 66766 | E10: 10000 | F10: 3336 | G10: =F10+D11+E10 -> 13336 | H10: =G10-I10-J10 -> 13176 | I10: 0 | J10: 160 | K10: 651795 | L10: =DGs!O11 -> 93569.8 | M10: =(L10+K10)/G10 -> 55.891182 | N10: =F10/G10 -> 0.25014997
B11: 45839 | C11: KWh
B12: 45870 | C12: KWh
B13: 45901 | C13: KWh
B14: 45931 | C14: KWh
B15: 45962 | C15: KWh
B16: 45992 | C16: KWh
B17: Total | C17: KWh | D17: =+SUM(D5:D16) -> 351777 | F17: =+SUM(F5:F16) -> 16281 | G17: =+D17+F17 -> 368058 | H17: =+SUM(H5:H16) -> 341888 | I17: =+SUM(I5:I16) -> 4476 | J17: =+SUM(J5:J16) -> 960 | K17: =+SUM(K5:K16) -> 3814831 | L17: =+SUM(L5:L16) -> 429950.88 | M17: =+AVERAGE(M5:M16) -> 17.452183 | N17: =F17/G17 -> 0.044234876
D18: =D17/G17 -> 0.95576512 | F18: =F17/G17 -> 0.044234876
F24: =D13-2692-1078 -> -3770

Sheet Water Data
A3: Month | B3: UOM | C3: Withdrawal | I3: Distribution | L3: Total Demand | M3: Recycle %
C4: Tanker water | D4: Ground Water | E4: Total Fresh Water Withdrawal | F4: Recycled Water | I4: Total Water Consumption | P4: Cost of Tanker Water | Q4: Total Cost Incurred
F5: Boiler Condensate | G5: RO for Toilet Flushing | H5: Total | I5: In Washing/ Dyeing | J5: In Domestic | K5: In Boiler | N5: STP
N6: Treated | P6: Rs./kl | Q6: Rs.
A7: 45658 | B7: kl | C7: 0 | D7: 1641 | E7: =D7+C7 -> 1641 | F7: 45.9 | G7: 174 | H7: =G7+F7 -> 219.9 | I7: 5.2 | J7: =L7-I7-K7 -> 1809.8 | K7: =F7 -> 45.9 | L7: =H7+E7 -> 1860.9 | M7: =H7/L7 -> 0.11816863 | N7: 1303
A8: 45689 | C8: 0 | D8: 1653 | E8: =D8+C8 -> 1653 | F8: 40.1 | G8: 168 | H8: =G8+F8 -> 208.1 | I8: 5.2 | J8: =L8-I8-K8 -> 1815.8 | K8: =F8 -> 40.1 | L8: =H8+E8 -> 1861.1 | M8: =H8/L8 -> 0.11181559 | N8: 1158
A9: 45717 | C9: 0 | D9: 1686 | E9: =D9+C9 -> 1686 | F9: 34.5 | G9: 202 | H9: =G9+F9 -> 236.5 | I9: 0 | J9: =L9-I9-K9 -> 1888 | K9: =F9 -> 34.5 | L9: =H9+E9 -> 1922.5 | M9: =H9/L9 -> 0.12301691 | N9: 1127 | Q9: =D9*P9 -> 0
A10: 45748 | C10: 0 | D10: 1670 | E10: =D10+C10 -> 1670 | F10: 33.3 | G10: 186 | H10: =G10+F10 -> 219.3 | I10: 6.3 | J10: =L10-I10-K10 -> 1849.7 | K10: =F10 -> 33.3 | L10: =H10+E10 -> 1889.3 | M10: =H10/L10 -> 0.11607474 | N10: 1248 | Q10: =D10*P10 -> 0
A11: 45778 | C11: 0 | D11: 1659 | E11: =D11+C11 -> 1659 | F11: 52.2 | G11: 205 | H11: =G11+F11 -> 257.2 | I11: 7.8 | J11: =L11-I11-K11 -> 1856.2 | K11: =F11 -> 52.2 | L11: =H11+E11 -> 1916.2 | M11: =H11/L11 -> 0.13422398 | N11: 764 | Q11: =D11*P11 -> 0
A12: 45809 | C12: 0 | D12: 1693 | E12: =D12+C12 -> 1693 | F12: 51.4 | G12: 212 | H12: =G12+F12 -> 263.4 | I12: 6.8 | J12: =L12-I12-K12 -> 1898.2 | K12: =F12 -> 51.4 | L12: =H12+E12 -> 1956.4 | M12: =H12/L12 -> 0.13463504 | N12: 1512 | Q12: =D12*P12 -> 0
A13: 45839 | C13: 0 | D13: 1733 | E13: =D13+C13 -> 1733 | F13: 37.6 | G13: 186 | H13: =G13+F13 -> 223.6 | I13: 8.6 | J13: 1924.7 | K13: =F13 -> 37.6 | L13: =H13+E13 -> 1956.6 | M13: =H13/L13 -> 0.11427987 | N13: 1241 | Q13: =D13*P13 -> 0
A14: 45870 | Q14: =D14*P14 -> 0
A15: 45901 | Q15: =D15*P15 -> 0
A16: 45931 | Q16: =D16*P16 -> 0
A17: 45962 | Q17: =D17*P17 -> 0
A18: 45992 | C18: 0 | E18: =D18+C18 -> 0 | H18: =G18+F18 -> 0 | J18: =L18-I18-K18 -> 0 | L18: =H18+E18 -> 0 | M18: =H18/L18 -> #DIV/0! | Q18: =D18*P18 -> 0
C19: =SUM(C7:C18) -> 0 | D19: =SUM(D7:D18) -> 11735 | E19: =SUM(E7:E18) -> 11735 | F19: =SUM(F7:F18) -> 295 | G19: =SUM(G7:G18) -> 1333 | H19: =SUM(H7:H18) -> 1628 | I19: =SUM(I7:I18) -> 39.9 | J19: =SUM(J7:J18) -> 13042.4 | ... N19: =SUM(N7:N18) -> 8353
D21: =D15-177 -> -177 | I21: Note: Kindly check calculation | J21: Note: Kindly check calculation | N21: =13738/303 -> 45.339934

Sheet Domestic RO
B3: Reverse Osmosis Plant Performance
B5: Month | C5: Running Hours | D5: Raw Water Supplied | E5: Treated Water | F5: Reject Generated | G5: Efficiency of RO | H5: Treatment Cost Consumable
H6: Electricity (KWh) | I6: Cost (Rs./unit) | J6: Ancotreat 5691 kgs | K6: Cost (Rs./kg) | L6: Total Cost (Rs.) | M6: Total Cost on feed (Rs./m3) | N6: Total Cost on product (Rs./m3)
B7: 45658 | C7: 75 | D7: 277 | E7: 138.5 | F7: =D7/2 -> 138.5 | G7: =F7*1000/D7 -> 500 | H7: 100 | I7: ='Electrcity Data'!M5 -> 10.388894 | J7: 4 | K7: 311 | L7: =H7*I7+J7*K7 -> 2282.8894 | M7: =L7/D7 -> 8.2414781 | N7: =L7/E7 -> 16.482956
B8: 45689 | C8: 75 | D8: 292 | E8: 146 | F8: =D8/2 -> 146 | G8: =F8*1000/D8 -> 500 | H8: 100 | I8: ='Electrcity Data'!M6 -> 9.1966195 | J8: 4 | K8: 311 | L8: =H8*I8+J8*K8 -> 2163.662 | M8: =L8/D8 -> 7.4098012 | N8: =L8/E8 -> 14.819602
B9: 45717 | C9: 75 | D9: 299 | E9: 149.5 | F9: =D9/2 -> 149.5 | G9: =F9*1000/D9 -> 500 | H9: 100 | I9: ='Electrcity Data'!M7 -> 10.015294 | J9: 4 | K9: 311 | L9: =H9*I9+J9*K9 -> 2245.5294 | M9: =L9/D9 -> 7.5101319 | N9: =L9/E9 -> 15.020264
B10: 45748 | C10: 75 | D10: 304 | E10: 152 | F10: =D10/2 -> 152 | G10: =E10*100/D10 -> 50 | H10: 100 | I10: ='Electrcity Data'!M8 -> 10.736692 | J10: 4 | K10: 311 | L10: =H10*I10+J10*K10 -> 2317.6692 | M10: =L10/D10 -> 7.6239118 | N10: =L10/E10 -> 15.247824
B11: 45778 | C11: 78 | D11: 287 | E11: 143.5 | F11: =D11/2 -> 143.5 | G11: =E11*100/D11 -> 50 | H11: 100 | I11: ='Electrcity Data'!M9 -> 8.4844151 | J11: 4 | K11: 311 | L11: =H11*I11+J11*K11 -> 2092.4415 | M11: =L11/D11 -> 7.290737 | N11: =L11/E11 -> 14.581474
B12: 45809 | C12: 75 | D12: 286 | E12: 143 | F12: =D12/2 -> 143 | G12: =E12*100/D12 -> 50 | H12: 100 | I12: ='Electrcity Data'!M10 -> 55.891182 | J12: 4 | K12: 311 | L12: =H12*I12+J12*K12 -> 6833.1182 | M12: =L12/D12 -> 23.892022 | N12: =L12/E12 -> 47.784043
B13: 45839 | C13: 81 | D13: 287 | E13: 144 | F13: =D13/2 -> 143.5 | G13: =E13*100/D13 -> 50.174216 | H13: 100 | I13: ='Electrcity Data'!M11 -> 0 | J13: 4 | K13: 311 | L13: =H13*I13+J13*K13 -> 1244 | M13: =L13/D13 -> 4.3344948 | N13: =L13/E13 -> 8.6388889
B14: 45870
B15: 45901
B16: 45931
B17: 45962 | F17: =D17/2 -> 0 | G17: =E17*100/D17 -> #DIV/0! | I17: 11.587255 | L17: =H17*I17+J17*K17 -> 0 | M17: =L17/D17 -> #DIV/0! | N17: =L17/E17 -> #DIV/0!
B18: 45992 | F18: =D18/2 -> 0 | G18: =E18*100/D18 -> #DIV/0! | I18: ='Electrcity Data'!M16 -> 0 | L18: =H18*I18+J18*K18 -> 0 | M18: =L18/D18 -> #DIV/0! | N18: =L18/E18 -> #DIV/0!
C19: =SUM(C7:C18) -> 534 | D19: =SUM(D7:D18) -> 2032 | E19: =SUM(E7:E18) -> 1016.5 | F19: =SUM(F7:F18) -> 1016 | G19: =SUM(G7:G18) -> #DIV/0! | H19: =SUM(H7:H18) -> 700 | I19: =SUM(I7:I18) -> 116.30035 | J19: =SUM(J7:J18) -> 28 | ... N19: =SUM(N7:N18) -> #DIV/0!
C21: Note: As discussed, we don't have supporter meter inDrinking water RO area Hours calculated

Sheet Stack emission Reports
B2: Please write the results of third party against the month in which it has been carried out.
C5: Stack attached to 1 TPH boiler
C6: Internal Dia at the top | G6: 750 mm
C7: Month | D7: PM | E7: SOx | F7: NOx | G7: CO | H7: Av. Velocity of Flue gas | I7: Av. Temperature of Flue gas
D8: mg/Nm3 | H8: m/s | I8: *C
C9: 45658
C10: 45689
C11: 45717
C12: 45748
C13: 45778
C14: 45809 | D14: 40.7 | E14: 13.2 | F14: 20.4 | H14: 7.27 | I14: 188
C15: 45839
C16: 45870
C17: 45901
C18: 45931
C19: 45962
C20: 45992
C22: Stack attached to 125 KVA DG I | K22: Stack attached to 320 KVA DG II
C23: Internal Dia at the top | H23: 250 mm | K23: Internal Dia at the top | O23: 250 mm
C25: Month | D25: PM10 | E25: SOx | F25: NOx | G25: CO | H25: Av. Velocity of Flue gas | I25: Av. Temperature of Flue gas | K25: Month | L25: PM10 | M25: SOx | N25: NOx | O25: CO | P25: Av. Velocity of Flue gas | Q25: Av. Temperature of Flue gas
H26: m/s | I26: *C | L26: mg/Nm3 | P26: m/s | Q26: *C
C27: 45658 | K27: 45658
C28: 45689 | K28: 45689
C29: 45717 | K29: 45717
C30: 45748 | K30: 45748
C31: 45778 | K31: 45778
C32: 45809 | D32: 27.2 | E32: 5 | F32: 10.8 | H32: 7.22 | I32: 152 | K32: 45809
C33: 45839 | K33: 45839
C34: 45870 | K34: 45870
C35: 45901 | K35: 45901
C36: 45931 | K36: 45931
C37: 45962 | K37: 45962
C38: 45992 | K38: 45992
B44: Month | C44: PM10 | D44: PM2.5 | E44: SOx | F44: NOx | G44: C0 | H44: VOC | J44: PM10 | K44: PM2.5 | L44: SOx | M44: NOx | N44: C0 | O44: VOC | Q44: PM10 | R44: PM2.5 | S44: SOx | T44: NOx | U44: C0 | V44: VOC | W44: PM10 | X44: PM2.5 | Y44: SOx | Z44: NOx | AA44: C0 | AB44: VOC | AC44: SOx | AD44: NOx
C45: Sewing Section 1 | K45: Sewing Section-2 | R45: Cutting | W45: Spot wash | AB45: Between 2 Building
B46: 45658
B47: 45689
B48: 45717
B49: 45748
B50: 45778
...

Sheet Production 
B1: Production Details
A3: Month/year | B3: Total Production (pcs)
A4: 45658 | B4: 141086
A5: 45689 | B5: 135634
A6: 45717 | B6: 119122
A7: 45748 | B7: 102996
A8: 45778 | B8: 116082
A9: 45809 | B9: 120954
A10: 45839
A11: 45870
A12: 45901
A13: 45931
A14: 45962
A15: 45992
A16: Total | B16: =SUM(B4:B15) -> 735874

Sheet Washing Details
A2: Washing Details
A4: Month | B4: Total No. of Pieces | C4: Denim | D4: Non Denim | E4: Weight (kg) | F4: Average Wt. (g/pc)
A5: 45658 | B5: 14420 | C5: 0 | D5: 0 | E5: 4415 | F5: 306
A6: 45689 | B6: 29710 | C6: 0 | D6: 0 | E6: 3266 | F6: 110
A7: 45717 | B7: 0 | C7: 0 | D7: 0 | E7: 0 | F7: #DIV/0!
A8: 45748 | B8: 17550 | C8: 0 | D8: 0 | E8: 5705 | F8: 325
A9: 45778 | B9: 25320 | E9: 8717 | F9: 344
A10: 45809 | B10: 0 | C10: 0 | D10: 0 | F10: #DIV/0!
A11: 45839
A12: 45870
A13: 45901
A14: 45931
A15: 45962
A16: 45992
A17: Total | B17: =SUM(B5:B16) -> 87000 | C17: =SUM(C5:C16) -> 0 | D17: =SUM(D5:D16) -> 0 | E17: =SUM(E5:E16) -> 22103 | F17: =SUM(F5:F16) -> #DIV/0!
